## Promise

> 它让您能够把异步操作最终的成功返回值或者失败原因和相应的处理程序关联起来。 这样使得异步方法可以像同步方法那样返回值：异步方法并不会立即返回最终的值，而是会返回一个 *promise*，以便在未来某个时候把值交给使用者。

+ Promise 不是对回调的替代。
+ Promise 在回调代码和将要执行这个任务的异步代码之间提供了一种可靠的中间机制来管理回调。
+ Promise 的决议结果只有两种可能：完成或拒绝，附带一个可选的单个值。
  + 如果 Promise 完成，那么最终的值称为完成值；
  + 如果拒绝，那么最终的值称为原因（也就是“拒绝的原因”）。
  + Promise 只能被决议（完成或者拒绝）一次。之后再次试图完成或拒绝的动作都会被忽略。
  + 因此，一旦 Promise 被决议，它就是不变量，不会发生改变。



### 三种状态

- *待定（pending）*: 初始状态，既没有被兑现，也没有被拒绝。
- *已兑现（fulfilled）*: 意味着操作成功完成。
- *已拒绝（rejected）*: 意味着操作失败。



### 构造

+ ```js
  var p = new Promise( function(resolve,reject){ 
    // ..
  } );
  ```

  + 提供给构造器 Promise(..) 的两个参数都是函数，一般称为 resolve(..) 和 reject(..)。
  + 如果调用 reject(..)，这个 promise 被拒绝，如果有任何值传给 reject(..)，这个值就被设置为拒绝的原因值。
  + 如果调用 resolve(..) 且没有值传入，或者传入任何非 promise 值，这个 promise 就完成。
  + 如果调用 resove(..) 并传入另外一个 promise，这个 promise 就会采用传入的 promise 的状态(要么实现要么拒绝)——不管是立即还是最终。



### 链式调用

+ 我们可以用 `promise.then()`，`promise.catch()` 和 `promise.finally()` 这些方法将进一步的操作与一个变为 resolved 的 promise 关联起来。这些方法还会返回一个新生成的 promise 对象，这个对象可以被非强制性的用来做链式调用

+ Promise 有一个 then(..) 方法，接受一个或两个回调函数作为参数。前面的函数(如果存在的话)会作为 promise 成功完成后的处理函数。第二个函数(如果存在的话)会作为 promise 被显式拒绝后的处理函数，或者在决议过程中出现错误 / 异常的情况下的处理函数。

  + ```js
    function ajax(url) {
      return new Promise(function pr(resolve,reject){
        // 建立请求，最终会调用resolve(..)或者reject(..) 
      } );
    }
    
    // ..
    
    ajax("http://some.url.1")
      .then(
      	function fulfilled(contents){ 
          // 处理contents成功情况
        },
      	function rejected(reason){
          // 处理ajax出错原因 
        }
    	);
    ```

  + 如果某个参数被省略，或者不是一个有效的函数——通常是 null，那么一个默认替代函数就会被采用。默认的成功回调把完成值传出，默认的出错回调会传递拒绝原因值。

+ then(..) 和 catch(..) 都会自动构造并返回另外一个 promise 实例，这个实例连接到接受原来的 promise 的不管是完成或拒绝处理函数（实际调用的那个）的返回值。

  + ```js
    ajax("http://some.url.1")
      .then(
      	function fulfilled(contents){ 
          // 处理contents成功情况
        },
      	function rejected(reason){
          // 处理ajax出错原因 
        }
    	)
    	.then( function fulfilled(contents){
    		// contents来自于后续的ajax(..)调用，不管是哪个调用 
    	} );
    ```

  + 第一个 fulfilled(..) 内部的异常（即被拒绝的 promise）不会导致第一 个 rejected(..) 被调用，因为这个处理函数只响应第一个原始 promise 的决议。而第二个 promise 会接受这个拒绝，这个 promise 是在第二个 then(..) 上调用的。

  + 前面的代码片段中，我们没有监听拒绝，这意味着它会默默保持这个状态等待未来的观测。如果永远不通过 then(..) 或 catch(..) 调用来观察的话，它就会一直保持未处理状 态。

+ catch(..) 抓取错误

  + 当 promise 链中的任何内容失败并引发错误或拒绝 promise 时，则控制权会转到链中最近的 `catch()` 语句。
  
  + 如果在 `catch()` 内部引发错误，则可以附加第二个 `catch()`来处理，依此类推。
  
    + ```js
    new Promise((resolve, reject) => {
        throw new Error('outer 错误')
      })
        .catch(err => {
          throw new Error('inner 错误')
        })
        .catch(err => {
          console.error(err)		// Error: inner 错误
        })
      ```
      
      
    
  + ```js
    var p1 = new Promise(function(resolve, reject) {
      resolve('Success');
    });
    
    p1.then(function(value) {
      console.log(value); // "Success!"
      throw 'oh, no!';
    }).catch(function(e) {
      console.log(e); // "oh, no!"
    }).then(function(){
      console.log('after a catch the chain is restored'); // “after a catch the chain is restored”
    }, function () {
      console.log('Not fired due to the catch');
    });
    
    p1.then(function(value) {
      console.log(value); // "Success!"
      throw 'oh, no!';
    }).then(function(){
      console.log('after a catch the chain is restored');
    }, function () {
      console.log('Not fired due to the catch'); // “Not fired due to the catch”
    }).catch(function(e) {
      console.log(e);
    });
    
    p1.then(function(value) {
      console.log(value); // "Success!"
      throw 'error 1';
    }).then(function(value){
      console.log(value);
      throw 'error 2';
    }, function (error) {
      console.log(error); // "error 1"
    }).catch(function() {
      console.log('catch by catch');
    });
    ```

### Thenable

+ Promise(..) 构造器的真正实例是 Promise。但还有一些类 promise 对象，称为 thenable，一般来说，它们也可以用 Promise 机制解释。

+ 任何提供了 then(..) 函数的对象(或函数)都被认为是 thenable。Promise 机制中所有可以接受真正 promise 状态的地方，也都可以处理 thenable。

+ 从根本上说，thenable 就是所有类 promise 值的一个通用标签，这些类 promise 不是被真正的 Promise(..) 构造器而是被其他系统创造出来。从这个角度来说，通常 thenable 的可靠性要低于真正的 Promise。

  + ```js
    var th = {
    	then: function thener( fulfilled ) {
    		// 每100ms调用一次fulfilled(..)，直到永远
    		setInterval( fulfilled, 100 );
    	}
    };
    
    th.then(res => console.log(res))	// 一直输出
    ```

  + 如果接收到了这个 thenable，并通过 th.then(..) 把它链接起来，很可能你会吃惊地发现自己的完成处理函数会被重复调用，而正常的 Promise 应该只会决议一次。

  + 一般来说，如果从某个其他系统接收到一个自称 promise 或者 thenable 的东西，不应该盲 目信任它。ES6 Promise 包含的一些工具，可以用来帮助解决这个信任问题。

### Promise API

#### Promise.resolve(..)

+ Promise.resolve(..) 创建了一个决议到传入值的 promise。

+ ```js
  var p1 = Promise.resolve( 42 );
  
  var p2 = new Promise( function pr(resolve){
  	resolve( 42 );
  } );
  ```

  + p1 和 p2 的最终行为方式是完全相同的。

+ 对于任何还没有完全确定是可信 promise 的值，甚至它可能是立即值，都可以通过把它传给 Promise.resolve(..) 来规范化。如果这个值已经是可以确定的 promise 或者 thenable，它的状态 / 决议就会被直接采用，这样会避免出错。而如果它是一个立即值，那么它会被“封装”为一个真正的promise，这样就把它的行为方式规范为异步的。

#### Promise.reject(..)

+ Promise.reject(..) 创建一个立即被拒绝的 promise。

+ ```js
  var p1 = Promise.reject( "Oops" );
  var p2 = new Promise( function pr(resolve,reject){ 
    reject( "Oops" );
  } );
  ```

+ resolve(..) 和 Promise.resolve(..) 可以接受 promise 并接受它的状态 / 决议，而 reject (..) 和 Promise.reject(..) 并不区分接收的值是什么。所以，如果传入 promise 或 thenable 来拒绝，这个 promise / thenable 本身会被设置为拒绝原因，而不是其底层值。

#### Promise.all([..])

+ Promise.all([ .. ]) 接受一个或多个值的数组(比如，立即值、promise、thenable)。它返回一个 promise，如果所有的值都完成，这个 promise 的结果是完成;一旦它们中的某一个被拒绝，那么这个 promise 就立即被拒绝。

+ ```js
  var p1 = Promise.resolve( 42 );
  var p2 = new Promise( function pr(resolve){
    setTimeout( function(){
      resolve( 43 );
    }, 100 ); 
  } );
  var v3 = 44;
  var p4 = new Promise( function pr(resolve,reject){
    setTimeout( function(){ 
      reject( "Oops" );
    }, 10); 
  } );
  
  Promise.all( [p1,p2,v3] )
  .then( function fulfilled(vals){
    console.log( vals );    			// [42,43,44]
  } );
  
  Promise.all( [p1,p2,v3,p4] ) 
  .then(
    function fulfilled(vals){ 
      // 不会到达这里
    },
    function rejected(reason){
      console.log( reason );			// Oops
    } 
  );
  ```

#### Promise.race([..])

+ Promise.all([ .. ]) 等待所有都完成(或者第一个拒绝)，而 Promise.race([ .. ]) 等待第一个完成或者拒绝。

+ ```js
  const first = new Promise((resolve, reject) => {
    setTimeout(resolve, 500, '第一个')
  })
  const second = new Promise((resolve, reject) => {
    setTimeout(resolve, 100, '第二个')
  })
  
  Promise.race([first, second]).then(result => {
    console.log(result) // 第二个
  })
  ```

+ ```js
  Promise.race( [p2,p1,v3] ) 
  .then( function fulfilled(val){
    console.log( val ); 					// 42
  } );
  
  Promise.race( [p2,p4] ) 
  .then(
    function fulfilled(val){ 
      // 不会到达这里
    },
    function rejected(reason){
      console.log( reason );			// Oops
    }
  );
  ```

+ Promise.all([]) 将会立即完成(没有完成值)，Promise.race([]) 将会永远挂起。不要用空数组使用这些 方法。

### 中断 Promise

+ Promises/A+标准：原Promise对象的状态将跟新对象保持一致。

  + 利用这一特性，当新对象保持“pending”状态时，原Promise链将会中止执行。

  + ```js
    Promise.resolve().then(() => {
        console.log('ok1')
        return new Promise(()=>{})  // 返回“pending”状态的Promise对象
    }).then(() => {
        // 后续的函数不会被调用
        console.log('ok2')
    }).catch(err => {
        console.log('err->', err)
    })
    
    // ok1
    // Promise {<pending>}
    ```

  + ```JS
    Promise.resolve().then(() => {
        console.log('ok1')
    }).then(() => {
        // 后续的函数不会被调用
        console.log('ok2')
    }).catch(err => {
        console.log('err->', err)
    })
    
    // ok1
    // ok2
    // Promise {<fulfilled>: undefined}
    ```

+ Promise.race 竞速方法，等待第一个完成或者拒绝。

  + 利用这一特性，也能达到后续的 Promise 不再执行。

  + ```js
    let p1 = new Promise((resolve, reject) => {
        resolve('ok1')
    })
    
    let p2 = new Promise((resolve, reject) => {
        setTimeout(() => {resolve('ok2')}, 10)
    })
    
    Promise.race([p2, p1]).then((result) => {
        console.log(result) 			//ok1
    }).catch((error) => {
        console.log(error)
    })
    ```

+ 当Promise链中抛出一个错误时，错误信息沿着链路向后传递，直至被捕获。

  + 利用这一特性能跳过链中被捕获前的函数的调用，直至链路终点。

  + ```js
    Promise.resolve().then(() => {
        console.log('ok1')
        throw 'throw error1'
    }).then(() => {
        console.log('ok2')
    }, err => {     
        // 捕获错误
        console.log('err->', err)
    }).then(() => {   
        // 该函数将被调用
        console.log('ok3')
        throw 'throw error3'
    }).then(() => {
        // 错误捕获前的函数不会被调用
        console.log('ok4')
    }).catch(err => {
        console.log('err->', err)
    })
    
    // ok1
    // err-> throw error1
    // ok3
    // err-> throw error3
    ```



## Async 和 Await

> 异步函数是 promise 和生成器的组合，基本上，它们是 promise 的更高级别的抽象。 而 async/await 建立在 promise 之上。

### 工作原理

+ 异步函数会返回 promise

  + ```js
    const doSomethingAsync = () => {
      return new Promise(resolve => {
        setTimeout(() => resolve('做些事情'), 3000)
      })
    }
    ```

### 使用

+ 当要调用此函数时，则在前面加上 `await`，然后调用的代码就会停止直到 promise 被解决或被拒绝。 注意：客户端函数必须被定义为 `async`。

  + ```js
    const doSomething = async () => {
      console.log(await doSomethingAsync())
    }
    ```

+ 在任何函数之前加上 `async` 关键字意味着该函数会返回 promise。即使没有显式地这样做，它也会在内部使它返回 promise。

  + ```js
    const aFunction = async () => {
      return '测试'
    }
    
    aFunction().then(alert) // 这会 alert '测试'
    
    // ====== 这与以下代码一样： =======
    
    const aFunction = () => {
      return Promise.resolve('测试')
    }
    
    aFunction().then(alert) // 这会 alert '测试'
    ```


+ 异步函数可以很容易地链接起来，并且语法比普通的 promise 更具可读性

  + ```js
    const promiseToDoSomething = () => {
      return new Promise(resolve => {
        setTimeout(() => resolve('做些事情'), 10000)
      })
    }
    
    const watchOverSomeoneDoingSomething = async () => {
      const something = await promiseToDoSomething()
      return something + ' 查看'
    }
    
    const watchOverSomeoneWatchingSomeoneDoingSomething = async () => {
      const something = await watchOverSomeoneDoingSomething()
      return something + ' 再次查看'
    }
    
    watchOverSomeoneWatchingSomeoneDoingSomething().then(res => {
      console.log(res)
    })
    
    // 做些事情 查看 再次查看
    ```

### 调试

+ 调试 promise 很难，因为调试器不会跳过异步的代码。Async/await 使这非常容易，因为对于编译器而言，它就像同步代码一样。

+ 捕获错误

  + ```js
    async function someFunction() {
      try {
        await someOtherFunction()
      } catch (err) {
        console.error(err.message)
      }
    }
    ```



## Reference Links

你不知道的 JavaScript 下：第四章

[nodejs 官方文档：入门教程](http://nodejs.cn/learn/modern-asynchronous-javascript-with-async-and-await)

